<?xml version="1.0"?>
<robot xmlns:xacro="http://wiki.ros.org/xacro">

  <xacro:macro name="kuka_kr150_2" params="prefix">
    <!-- LINKS -->
    <!-- base link -->
    <link name="${prefix}base_link">
      <visual>
        <origin rpy="0 0 0" xyz="0 0 0"/>
        <geometry>
          <mesh filename="package://kr150_description/meshes/kr150_2/visual/base_link.dae" />
        </geometry>
      </visual>
      <collision>
        <origin rpy="0 0 0" xyz="0 0 0"/>
        <geometry>
          <mesh filename="package://kr150_description/meshes/kr150_2/collision/base_link.stl" />
        </geometry>
      </collision>
      <inertial>
        <mass value="202"/>
        <origin rpy="0 0 0" xyz="0 0 0"/>
        <inertia ixx="18026640.942" ixy="-63776.874" ixz="-12034.191" iyy="15517698.140" iyz="-681592.618" izz="202.949"/>
      </inertial>
    </link>
    <!-- link 1 (A1) -->
    <link name="${prefix}link_1">
      <visual>
        <origin xyz="0 0 0" rpy="0 0 0"/>
        <geometry>
          <mesh filename="package://kr150_description/meshes/kr150_2/visual/link_1.dae" />
        </geometry>
      </visual>
      <collision>
        <origin xyz="0 0 0" rpy="0 0 0"/>
        <geometry>
          <mesh filename="package://kr150_description/meshes/kr150_2/collision/link_1.stl" />
        </geometry>
      </collision>
      <inertial>
        <mass value="113.789"/>
        <origin rpy="0 0 0" xyz="0 0 0"/>
        <inertia ixx="44256438.988" ixy="1515407.021" ixz="-3751903.667" iyy="38433645.587" iyz="3947019.941" izz="13879163.755"/>
      </inertial>
    </link>
    <!-- link 2 -->
    <link name="${prefix}link_2">
      <visual>
        <origin xyz="0 0 0" rpy="0 0 0"/>
        <geometry>
          <mesh filename="package://kr150_description/meshes/kr150_2/visual/link_2.dae"/>
        </geometry>
      </visual>
      <collision>
        <origin xyz="0 0 0" rpy="0 0 0"/>
        <geometry>
          <mesh filename="package://kr150_description/meshes/kr150_2/collision/link_2.stl"  />
        </geometry>
      </collision>
      <inertial>
        <mass value="128.289"/>
        <origin rpy="0 0 0" xyz="0 0 0"/>
        <inertia ixx="222759248.246" ixy="10917339.332" ixz="37965297.844 " iyy="212779494.067 " iyz="55858617.185" izz="26730538.796"/>
      </inertial>      
    </link>
    <!-- link 3 -->
    <link name="${prefix}link_3">
      <visual>
        <origin xyz="0 0 0" rpy="0 0 0"/>
        <geometry>
          <mesh filename="package://kr150_description/meshes/kr150_2/visual/link_3.dae" />
        </geometry>
      </visual>
      <collision>
        <origin xyz="0 0 0" rpy="0 0 0"/>
        <geometry>
          <mesh filename="package://kr150_description/meshes/kr150_2/collision/link_3.stl"  />
        </geometry>
      </collision>
      <inertial>
        <mass value="55.264" />
        <origin rpy="0 0 0" xyz="0 0 0"/>
        <inertia ixx="227283567.242 " ixy="-444134.292" ixz="2398080.124" iyy="212960722.458" iyz="50905692.306" izz="14911487.072"/>
      </inertial>      
    </link>
    <!-- link 4 -->
    <link name="${prefix}link_4">
      <visual>
        <origin xyz="0 0 0" rpy="0 0 0"/>
        <geometry>
          <mesh filename="package://kr150_description/meshes/kr150_2/visual/link_4.dae" />
        </geometry>
      </visual>
      <collision>
        <origin xyz="0 0 0" rpy="0 0 0"/>
        <geometry>
          <mesh filename="package://kr150_description/meshes/kr150_2/collision/link_4.stl"  />
        </geometry>
      </collision>
      <inertial>
        <mass value="222.414"/>
        <origin rpy="0 0 0" xyz="0 0 0"/>
        <inertia ixx="116690317.289 " ixy=" -217478.502" ixz="319180.825 " iyy="85032110.170" iyz="51420359.377" izz="32000704.547"/>
      </inertial>      
    </link>
    <!-- link 5 -->
    <link name="${prefix}link_5">
      <visual>
        <origin xyz="0 0 0" rpy="0 0 0"/>
        <geometry>
          <mesh filename="package://kr150_description/meshes/kr150_2/visual/link_5.dae" />
        </geometry>
      </visual>
      <collision>
        <origin xyz="0 0 0" rpy="0 0 0"/>
        <geometry>
          <mesh filename="package://kr150_description/meshes/kr150_2/collision/link_5.stl" />
        </geometry>
      </collision>
      <inertial>
        <mass value="9.312"/>
        <origin rpy="0 0 0" xyz="0 0 0"/>
        <inertia ixx="56095774.637" ixy="350435.185" ixz="470622.777" iyy="35284894.395" iyz="27055480.349" izz="20872134.322"/>
      </inertial>      
    </link>
    <!-- link 6 -->
    <link name="${prefix}link_6">
      <visual>
        <origin xyz="0 0 0" rpy="0 0 0"/>
        <geometry>
          <mesh filename="package://kr150_description/meshes/kr150_2/visual/link_6.dae" />
        </geometry>
      </visual>
      <collision>
        <origin xyz="0 0 0" rpy="0 0 0"/>
        <geometry>
          <mesh filename="package://kr150_description/meshes/kr150_2/collision/link_6.stl" />
        </geometry>
      </collision>
      <inertial>
        <mass value="23.085357"/>
        <origin rpy="0 0 0" xyz="0 0 0"/>
        <inertia ixx="0.343576" ixy="-0.000062" ixz="-0.002079" iyy="0.336217" iyz="-0.000014" izz="0.334050"/>
      </inertial> 
      
    </link>
    <!-- tool link -->
    <!-- This frame corresponds to the $TOOL coordinate system in KUKA KRC controllers. -->
    <link name="${prefix}flange"/>
    <!-- END LINKS -->

    <!-- JOINTS -->
    <!-- joint 1 (A1) -->
    <joint name="${prefix}joint_a1" type="revolute">
      <origin xyz="0 0 0.75" rpy="0 0 0"/>
      <parent link="${prefix}base_link"/>
      <child link="${prefix}link_1"/>
      <axis xyz="0 0 -1"/>
      <limit effort="0" lower="${radians(-185)}" upper="${radians(185)}" velocity="${radians(110)}"/>
    </joint>
    <!-- joint 2 (A2) -->
    <joint name="${prefix}joint_a2" type="revolute">
      <origin xyz="0.35 0 0" rpy="0 0 0"/>
      <parent link="${prefix}link_1"/>
      <child link="${prefix}link_2"/>
      <axis xyz="0 1 0"/>
      <limit effort="0" lower="${radians(-146)}" upper="${radians(0)}" velocity="${radians(110)}"/>
    </joint>
    <!-- joint 3 (A3) -->
    <joint name="${prefix}joint_a3" type="revolute">
      <origin xyz="1.25 0 0" rpy="0 0 0"/>
      <parent link="${prefix}link_2"/>
      <child link="${prefix}link_3"/>
      <axis xyz="0 1 0"/>
      <limit effort="0" lower="${radians(-119)}" upper="${radians(155)}" velocity="${radians(100)}"/>
    </joint>
    <!-- joint 4 (A4) -->
    <joint name="${prefix}joint_a4" type="revolute">
      <origin xyz="0 0 -0.055" rpy="0 0 0"/>
      <parent link="${prefix}link_3"/>
      <child link="${prefix}link_4"/>
      <axis xyz="-1 0 0"/>
      <limit effort="0" lower="${radians(-350)}" upper="${radians(350)}" velocity="${radians(170)}"/>
    </joint>
    <!-- joint 5 (A5) -->
    <joint name="${prefix}joint_a5" type="revolute">
      <origin xyz="1.1 0 0" rpy="0 0 0"/>
      <parent link="${prefix}link_4"/>
      <child link="${prefix}link_5"/>
      <axis xyz="0 1 0"/>
      <limit effort="0" lower="${radians(-125)}" upper="${radians(125)}" velocity="${radians(170)}"/>
    </joint>
    <!-- joint 6 (A6) -->
    <joint name="${prefix}joint_a6" type="revolute">
      <origin xyz="0.23 0 0" rpy="0 0 0"/>
      <parent link="${prefix}link_5"/>
      <child link="${prefix}link_6"/>
      <axis xyz="-1 0 0"/>
      <limit effort="0" lower="${radians(-350)}" upper="${radians(350)}" velocity="${radians(238)}"/>
    </joint>
    <!-- tool frame - fixed frame -->
    <joint name="${prefix}joint_a6-flange" type="fixed">
      <parent link="${prefix}link_6"/>
      <child link="${prefix}flange"/>
      <origin xyz="0 0 0" rpy="0 0 0"/>
    </joint>
    <!-- END JOINTS -->

    <!-- ROS base_link to KUKA $ROBROOT coordinate system transform -->
    <link name="${prefix}base" />
    <joint name="${prefix}base_link-base" type="fixed">
      <origin xyz="0 0 0" rpy="0 0 0"/>
      <parent link="${prefix}base_link"/>
      <child link="${prefix}base"/>
    </joint>

    <!-- This frame corresponds to the $TOOL coordinate system in KUKA KRC controllers -->
    <link name="${prefix}tool0" />
    <joint name="${prefix}flange-tool0" type="fixed">
      <parent link="${prefix}flange"/>
      <child link="${prefix}tool0"/>
      <origin xyz="0 0 0" rpy="0 ${radians(90)} 0"/>
    </joint>
    
  </xacro:macro>
</robot>
