<?xml version="1.0"?>
<robot xmlns:xacro="http://wiki.ros.org/xacro">

  <xacro:macro name="kuka_kr150_2" params="prefix">
    <!-- LINKS -->
    <!-- base link -->
    <link name="${prefix}base_link">
      <visual>
        <origin rpy="0 0 0" xyz="0 0 0"/>
        <geometry>
          <mesh filename="package://kr150_description/meshes/kr150_2/visual/base_link.dae" />
        </geometry>
      </visual>
      <collision>
        <origin rpy="0 0 0" xyz="0 0 0"/>
        <geometry>
          <mesh filename="package://kr150_description/meshes/kr150_2/collision/base_link.stl" />
        </geometry>
      </collision>
      <inertial>
        <mass value="202.0"/>
        <!--          origen de esta inercia-->
        <origin rpy="0 0 0" xyz="0 0 0"/>
        <inertia ixx="18.02664" ixy="-0.0638" ixz="-0.012" iyy="15.5177" iyz="-0.6815" izz="0.000202949"/>
      </inertial>
    </link>
    <!-- link 1 (A1) -->
    <link name="${prefix}link_1">
      <visual>
        <origin xyz="0 0 0" rpy="0 0 0"/>
        <geometry>
          <mesh filename="package://kr150_description/meshes/kr150_2/visual/link_1.dae" />
        </geometry>
      </visual>
      <collision>
        <origin xyz="0 0 0" rpy="0 0 0"/>
        <geometry>
          <mesh filename="package://kr150_description/meshes/kr150_2/collision/link_1.stl" />
        </geometry>
      </collision>
      <inertial>
        <mass value="113.789"/>
        <origin rpy="0 0 0" xyz="0 0 0"/>
        <inertia ixx="44.25643" ixy="1.51540" ixz="-3.75190" iyy="38.43364" iyz="3.94701" izz="13.87916"/>
      </inertial>
    </link>
    <!-- link 2 -->
    <link name="${prefix}link_2">
      <visual>
        <origin xyz="0 0 0" rpy="0 0 0"/>
        <geometry>
          <mesh filename="package://kr150_description/meshes/kr150_2/visual/link_2.dae"/>
        </geometry>
      </visual>
      <collision>
        <origin xyz="0 0 0" rpy="0 0 0"/>
        <geometry>
          <mesh filename="package://kr150_description/meshes/kr150_2/collision/link_2.stl"  />
        </geometry>
      </collision>
      <inertial>
        <mass value="128.289"/>
        <origin rpy="0 0 0" xyz="0 0 0"/>
        <inertia ixx="222.75924" ixy="10.91733" ixz="37.96529" iyy="212.77949" iyz="55.85861" izz="26.73053"/>
      </inertial>      
    </link>
    <!-- link 3 -->
    <link name="${prefix}link_3">
      <visual>
        <origin xyz="0 0 0" rpy="0 0 0"/>
        <geometry>
          <mesh filename="package://kr150_description/meshes/kr150_2/visual/link_3.dae" />
        </geometry>
      </visual>
      <collision>
        <origin xyz="0 0 0" rpy="0 0 0"/>
        <geometry>
          <mesh filename="package://kr150_description/meshes/kr150_2/collision/link_3.stl"  />
        </geometry>
      </collision>
      <inertial>
        <mass value="55.264" />
        <origin rpy="0 0 0" xyz="0 0 0"/>
        <inertia ixx="227.28356" ixy="-0.44413" ixz="2.39808" iyy="212.96072" iyz="50.90569" izz="14.91148"/>
      </inertial>      
    </link>
    <!-- link 4 -->
    <link name="${prefix}link_4">
      <visual>
        <origin xyz="0 0 0" rpy="0 0 0"/>
        <geometry>
          <mesh filename="package://kr150_description/meshes/kr150_2/visual/link_4.dae" />
        </geometry>
      </visual>
      <collision>
        <origin xyz="0 0 0" rpy="0 0 0"/>
        <geometry>
          <mesh filename="package://kr150_description/meshes/kr150_2/collision/link_4.stl"  />
        </geometry>
      </collision>
      <inertial>
        <mass value="222.414"/>
        <origin rpy="0 0 0" xyz="0 0 0"/>
        <inertia ixx="116.69031" ixy=" -0.21747" ixz="0.31918" iyy="85.03211" iyz="51.42035" izz="32.00070"/>
      </inertial>      
    </link>
    <!-- link 5 -->
    <link name="${prefix}link_5">
      <visual>
        <origin xyz="0 0 0" rpy="0 0 0"/>
        <geometry>
          <mesh filename="package://kr150_description/meshes/kr150_2/visual/link_5.dae" />
        </geometry>
      </visual>
      <collision>
        <origin xyz="0 0 0" rpy="0 0 0"/>
        <geometry>
          <mesh filename="package://kr150_description/meshes/kr150_2/collision/link_5.stl" />
        </geometry>
      </collision>
      <inertial>
        <mass value="9.312"/>
        <origin rpy="0 0 0" xyz="0 0 0"/>
        <inertia ixx="56.09577" ixy="0.35043" ixz="0.47062" iyy="35.2848" iyz="27.05548" izz="20.8721"/>
      </inertial>      
    </link>
    <!-- link 6 -->
    <link name="${prefix}link_6">
      <visual>
        <origin xyz="0 0 0" rpy="0 0 0"/>
        <geometry>
          <mesh filename="package://kr150_description/meshes/kr150_2/visual/link_6.dae" />
        </geometry>
      </visual>
      <collision>
        <origin xyz="0 0 0" rpy="0 0 0"/>
        <geometry>
          <mesh filename="package://kr150_description/meshes/kr150_2/collision/link_6.stl" />
        </geometry>
      </collision>
      <inertial>
        <mass value="20.815"/>
        <origin rpy="0 0 0" xyz="0 0 0"/>
        <inertia ixx="5.33544" ixy="-0.000020453" ixz="0.000023961" iyy="3.08644" iyz="2.63404" izz="2.25310"/>
      </inertial> 
      
    </link>
    <!-- tool link -->
    <!-- This frame corresponds to the $TOOL coordinate system in KUKA KRC controllers. -->
    <link name="${prefix}flange"/>
    <!-- END LINKS -->

    <!-- JOINTS -->
    <!-- joint 1 (A1) -->
    <joint name="${prefix}joint_a1" type="revolute">
      <origin xyz="0 0 0.75" rpy="0 0 0"/>
      <parent link="${prefix}base_link"/>
      <child link="${prefix}link_1"/>
      <axis xyz="0 0 -1"/>
      <limit effort="692" lower="${radians(-185)}" upper="${radians(185)}" velocity="${radians(110)}"/>
      <dynamics damping="0.0" friction="0.0"/>
    </joint>
    <!-- joint 2 (A2) -->
    <joint name="${prefix}joint_a2" type="revolute">
      <origin xyz="0.35 0 0" rpy="0 0 0"/>
      <parent link="${prefix}link_1"/>
      <child link="${prefix}link_2"/>
      <axis xyz="0 1 0"/>
      <limit effort="574" lower="${radians(-146)}" upper="${radians(0)}" velocity="${radians(110)}"/>
      <dynamics damping="0.0" friction="0.0"/>
    </joint>
    <!-- joint 3 (A3) -->
    <joint name="${prefix}joint_a3" type="revolute">
      <origin xyz="1.25 0 0" rpy="0 0 0"/>
      <parent link="${prefix}link_2"/>
      <child link="${prefix}link_3"/>
      <axis xyz="0 1 0"/>
      <limit effort="242" lower="${radians(-119)}" upper="${radians(155)}" velocity="${radians(100)}"/>
      <dynamics damping="0.0" friction="0.0"/>
    </joint>
    <!-- joint 4 (A4) -->
    <joint name="${prefix}joint_a4" type="revolute">
      <origin xyz="0 0 -0.055" rpy="0 0 0"/>
      <parent link="${prefix}link_3"/>
      <child link="${prefix}link_4"/>
      <axis xyz="-1 0 0"/>
      <limit effort="58" lower="${radians(-350)}" upper="${radians(350)}" velocity="${radians(170)}"/>
      <dynamics damping="0.0" friction="0.0"/>
    </joint>
    <!-- joint 5 (A5) -->
    <joint name="${prefix}joint_a5" type="revolute">
      <origin xyz="1.1 0 0" rpy="0 0 0"/>
      <parent link="${prefix}link_4"/>
      <child link="${prefix}link_5"/>
      <axis xyz="0 1 0"/>
      <limit effort="29" lower="${radians(-125)}" upper="${radians(125)}" velocity="${radians(170)}"/>
      <dynamics damping="0.0" friction="0.0"/>
    </joint>
    <!-- joint 6 (A6) -->
    <joint name="${prefix}joint_a6" type="revolute">
      <origin xyz="0.23 0 0" rpy="0 0 0"/>
      <parent link="${prefix}link_5"/>
      <child link="${prefix}link_6"/>
      <axis xyz="-1 0 0"/>
      <limit effort="29" lower="${radians(-350)}" upper="${radians(350)}" velocity="${radians(238)}"/>
      <dynamics damping="0.0" friction="0.0"/>
    </joint>
    <!-- tool frame - fixed frame -->
    <joint name="${prefix}joint_a6-flange" type="fixed">
      <parent link="${prefix}link_6"/>
      <child link="${prefix}flange"/>
      <origin xyz="0 0 0" rpy="0 0 0"/>
    </joint>
    <!-- END JOINTS -->

    <!-- ROS base_link to KUKA $ROBROOT coordinate system transform -->
    <link name="${prefix}base" />
    <joint name="${prefix}base_link-base" type="fixed">
      <origin xyz="0 0 0" rpy="0 0 0"/>
      <parent link="${prefix}base_link"/>
      <child link="${prefix}base"/>
    </joint>

    <!-- This frame corresponds to the $TOOL coordinate system in KUKA KRC controllers -->
    <link name="${prefix}tool0" />
    <joint name="${prefix}flange-tool0" type="fixed">
      <parent link="${prefix}flange"/>
      <child link="${prefix}tool0"/>
      <origin xyz="0 0 0" rpy="0 ${radians(90)} 0"/>
    </joint>
    
  </xacro:macro>
</robot>
